Process Consumer-2:
Traceback (most recent call last):
  File "/share/george2/miniconda/lib/python2.7/multiprocessing/process.py", line 258, in _bootstrap
    self.run()
  File "/gpfs_common/share/george2/Raise/parGALE/algorithms/parallel/multi.py", line 35, in run
    best_solutions, evals = self.optimizer.run(self.initial_pop)
  File "/gpfs_common/share/george2/Raise/parGALE/algorithms/parallel/gale/multi_gale.py", line 170, in run
    population, evals = self.recombine(selectees, self.settings.pop_size)
  File "/gpfs_common/share/george2/Raise/parGALE/algorithms/parallel/gale/multi_gale.py", line 110, in _recombine
    pop.append(self.problem.generate())
  File "/gpfs_common/share/george2/Raise/parGALE/problems/feature_models/base.py", line 64, in generate
    assert False, "Unsatisfiability reached"
AssertionError: Unsatisfiability reached
Traceback (most recent call last):
  File "runner.py", line 29, in <module>
    result_count = sum([len(soln) for i in range(num_consumers) for soln in results[i]])
  File "<string>", line 2, in __getitem__
  File "/share/george2/miniconda/lib/python2.7/multiprocessing/managers.py", line 774, in _callmethod
    raise convert_to_error(kind, result)
KeyError: 0
